INFO:zerotest.record.http_recorder:recorder service start, store http record to '/tmp/tmp5u1z014z'
INFO:werkzeug: * Restarting with stat
INFO:zerotest.record.http_recorder:recorder service start, store http record to '/tmp/tmp1topikzn'
WARNING:werkzeug: * Debugger is active!
INFO:werkzeug: * Debugger pin code: 327-990-162
DEBUG:zerotest.forwarder:forward to [GET]http://api.daocloud.io, headers: -----{'User-Agent': 'curl/7.38.0', 'Content-Type': '', 'Content-Length': '', 'Accept': '*/*'}-----
INFO:requests.packages.urllib3.connectionpool:Starting new HTTP connection (1): api.daocloud.io
DEBUG:requests.packages.urllib3.connectionpool:"GET /_ping HTTP/1.1" 400 None
DEBUG:zerotest.record.http_recorder:record http [GET]http://api.daocloud.io/_ping
{'User-Agent': 'curl/7.38.0', 'Content-Type': '', 'Content-Length': '', 'Accept': '*/*'}
b'', 400
{}

INFO:werkzeug:127.0.0.1 - - [21/Nov/2015 13:56:39] "GET /_ping HTTP/1.1" 400 -
DEBUG:zerotest.record.http_recorder:receive task (Request(headers={'User-Agent': 'curl/7.38.0', 'Content-Type': '', 'Content-Length': '', 'Accept': '*/*'}, method='GET', host='api.daocloud.io', path='/_ping', scheme='http'), Response(body='', status=400, headers={}))
Exception in thread Thread-1:
Traceback (most recent call last):
  File "/usr/local/lib/python3.5/threading.py", line 923, in _bootstrap_inner
    self.run()
  File "/usr/local/lib/python3.5/threading.py", line 871, in run
    self._target(*self._args, **self._kwargs)
  File "/usr/local/lib/python3.5/site-packages/zerotest-1.0.2-py3.5.egg/zerotest/record/http_recorder.py", line 48, in _loop_work
    self._formatter.write_record(record_file, task[0], task[1])
  File "/usr/local/lib/python3.5/site-packages/zerotest-1.0.2-py3.5.egg/zerotest/record/formatter.py", line 12, in write_record
    writeable.write('{}'.format(json.dumps(record)))
  File "/usr/local/lib/python3.5/json/__init__.py", line 230, in dumps
    return _default_encoder.encode(obj)
  File "/usr/local/lib/python3.5/json/encoder.py", line 199, in encode
    chunks = self.iterencode(o, _one_shot=True)
  File "/usr/local/lib/python3.5/json/encoder.py", line 257, in iterencode
    return _iterencode(o, 0)
  File "/usr/local/lib/python3.5/json/encoder.py", line 180, in default
    raise TypeError(repr(o) + " is not JSON serializable")
TypeError: b'' is not JSON serializable

DEBUG:zerotest.forwarder:forward to [GET]http://api.daocloud.io, headers: -----{'User-Agent': 'curl/7.38.0', 'Content-Type': '', 'Content-Length': '', 'Accept': '*/*'}-----
INFO:requests.packages.urllib3.connectionpool:Starting new HTTP connection (1): api.daocloud.io
DEBUG:requests.packages.urllib3.connectionpool:"GET /_ping HTTP/1.1" 400 None
DEBUG:zerotest.record.http_recorder:record http [GET]http://api.daocloud.io/_ping
{'User-Agent': 'curl/7.38.0', 'Content-Type': '', 'Content-Length': '', 'Accept': '*/*'}
b'', 400
{}

INFO:werkzeug:127.0.0.1 - - [21/Nov/2015 13:59:38] "GET /_ping HTTP/1.1" 400 -
DEBUG:zerotest.forwarder:forward to [GET]http://api.daocloud.io, headers: -----{'User-Agent': 'curl/7.38.0', 'Content-Type': '', 'Content-Length': '', 'Accept': '*/*'}-----
INFO:requests.packages.urllib3.connectionpool:Starting new HTTP connection (1): api.daocloud.io
DEBUG:requests.packages.urllib3.connectionpool:"GET /_ping HTTP/1.1" 400 None
DEBUG:zerotest.record.http_recorder:record http [GET]http://api.daocloud.io/_ping
{'User-Agent': 'curl/7.38.0', 'Content-Type': '', 'Content-Length': '', 'Accept': '*/*'}
b'', 400
{}

INFO:werkzeug:127.0.0.1 - - [21/Nov/2015 14:00:53] "GET /_ping HTTP/1.1" 400 -
